Watching for file changes with StatReloader
Exception in thread django-main-thread:
Traceback (most recent call last):
  File "D:\anaconda\lib\threading.py", line 973, in _bootstrap_inner
    self.run()
  File "D:\anaconda\lib\threading.py", line 910, in run
    self._target(*self._args, **self._kwargs)
  File "D:\anaconda\lib\site-packages\django\utils\autoreload.py", line 64, in wrapper
    fn(*args, **kwargs)
  File "D:\anaconda\lib\site-packages\django\core\management\commands\runserver.py", line 110, in inner_run
    autoreload.raise_last_exception()
  File "D:\anaconda\lib\site-packages\django\utils\autoreload.py", line 87, in raise_last_exception
    raise _exception[1]
  File "D:\anaconda\lib\site-packages\django\core\management\__init__.py", line 375, in execute
    autoreload.check_errors(django.setup)()
  File "D:\anaconda\lib\site-packages\django\utils\autoreload.py", line 64, in wrapper
    fn(*args, **kwargs)
  File "D:\anaconda\lib\site-packages\django\__init__.py", line 24, in setup
    apps.populate(settings.INSTALLED_APPS)
  File "D:\anaconda\lib\site-packages\django\apps\registry.py", line 91, in populate
    app_config = AppConfig.create(entry)
  File "D:\anaconda\lib\site-packages\django\apps\config.py", line 224, in create
    import_module(entry)
  File "D:\anaconda\lib\importlib\__init__.py", line 127, in import_module
    return _bootstrap._gcd_import(name[level:], package, level)
  File "<frozen importlib._bootstrap>", line 1030, in _gcd_import
  File "<frozen importlib._bootstrap>", line 1007, in _find_and_load
  File "<frozen importlib._bootstrap>", line 984, in _find_and_load_unlocked
ModuleNotFoundError: No module named 'corsheaders'
E:\project\软工后端\backend\djangoProject\djangoProject\settings.py changed, reloading.
Watching for file changes with StatReloader
Performing system checks...

System check identified no issues (0 silenced).
June 05, 2022 - 01:15:29
Django version 3.2.5, using settings 'djangoProject.settings'
Starting development server at http://0.0.0.0:8080/
Quit the server with CTRL-BREAK.
Exception in thread django-main-thread:
Traceback (most recent call last):
  File "D:\anaconda\lib\site-packages\django\core\servers\basehttp.py", line 45, in get_internal_wsgi_application
    return import_string(app_path)
  File "D:\anaconda\lib\site-packages\django\utils\module_loading.py", line 17, in import_string
    module = import_module(module_path)
  File "D:\anaconda\lib\importlib\__init__.py", line 127, in import_module
    return _bootstrap._gcd_import(name[level:], package, level)
  File "<frozen importlib._bootstrap>", line 1030, in _gcd_import
  File "<frozen importlib._bootstrap>", line 1007, in _find_and_load
  File "<frozen importlib._bootstrap>", line 986, in _find_and_load_unlocked
  File "<frozen importlib._bootstrap>", line 680, in _load_unlocked
  File "<frozen importlib._bootstrap_external>", line 850, in exec_module
  File "<frozen importlib._bootstrap>", line 228, in _call_with_frames_removed
  File "E:\project\软工后端\backend\djangoProject\djangoProject\wsgi.py", line 7, in <module>
    application = get_wsgi_application()
  File "D:\anaconda\lib\site-packages\django\core\wsgi.py", line 13, in get_wsgi_application
    return WSGIHandler()
  File "D:\anaconda\lib\site-packages\django\core\handlers\wsgi.py", line 127, in __init__
    self.load_middleware()
  File "D:\anaconda\lib\site-packages\django\core\handlers\base.py", line 40, in load_middleware
    middleware = import_string(middleware_path)
  File "D:\anaconda\lib\site-packages\django\utils\module_loading.py", line 17, in import_string
    module = import_module(module_path)
  File "D:\anaconda\lib\importlib\__init__.py", line 127, in import_module
    return _bootstrap._gcd_import(name[level:], package, level)
  File "<frozen importlib._bootstrap>", line 1030, in _gcd_import
  File "<frozen importlib._bootstrap>", line 1007, in _find_and_load
  File "<frozen importlib._bootstrap>", line 972, in _find_and_load_unlocked
  File "<frozen importlib._bootstrap>", line 228, in _call_with_frames_removed
  File "<frozen importlib._bootstrap>", line 1030, in _gcd_import
  File "<frozen importlib._bootstrap>", line 1007, in _find_and_load
  File "<frozen importlib._bootstrap>", line 984, in _find_and_load_unlocked
ModuleNotFoundError: No module named 'corsheaders'

The above exception was the direct cause of the following exception:

Traceback (most recent call last):
  File "D:\anaconda\lib\threading.py", line 973, in _bootstrap_inner
    self.run()
  File "D:\anaconda\lib\threading.py", line 910, in run
    self._target(*self._args, **self._kwargs)
  File "D:\anaconda\lib\site-packages\django\utils\autoreload.py", line 64, in wrapper
    fn(*args, **kwargs)
  File "D:\anaconda\lib\site-packages\django\core\management\commands\runserver.py", line 138, in inner_run
    handler = self.get_handler(*args, **options)
  File "D:\anaconda\lib\site-packages\django\contrib\staticfiles\management\commands\runserver.py", line 27, in get_handler
    handler = super().get_handler(*args, **options)
  File "D:\anaconda\lib\site-packages\django\core\management\commands\runserver.py", line 65, in get_handler
    return get_internal_wsgi_application()
  File "D:\anaconda\lib\site-packages\django\core\servers\basehttp.py", line 47, in get_internal_wsgi_application
    raise ImproperlyConfigured(
django.core.exceptions.ImproperlyConfigured: WSGI application 'djangoProject.wsgi.application' could not be loaded; Error importing module.
E:\project\软工后端\backend\djangoProject\djangoProject\settings.py changed, reloading.
Watching for file changes with StatReloader
Performing system checks...

System check identified no issues (0 silenced).
June 05, 2022 - 01:16:51
Django version 3.2.5, using settings 'djangoProject.settings'
Starting development server at http://0.0.0.0:8080/
Quit the server with CTRL-BREAK.
Error: [WinError 10013] 以一种访问权限不允许的方式做了一个访问套接字的尝试。
